<?xml version="1.0"?>
<robot xmlns:xacro="http://www.ros.org/wiki/xacro" >

    <xacro:include filename ="inertial_macros.xacro"/>

    <material name ="white">
        <color rgba="1 1 1 1" />
    </material>

    <material name ="orange">
        <color rgba="1 0.3 0.1 1" />
    </material>

    <material name ="blue">
        <color rgba="0.2 0.2 1 1" />
    </material>

    <material name ="black">
        <color rgba="0 0 0 1" />
    </material>

    <link name="base_link">

    </link>

    <joint name="chassis_joint" type="fixed">
        <parent link= "base_link"/>
        <child link="midle_chassis"/>
        <origin xyz="-0.069 0 0"/>
    </joint>

    <link name="midle_chassis">
        <visual>
            <origin xyz="0 0 0.0025"/>
            <geometry>
                <box size="0.2 0.15 0.005"/>
            </geometry>
            <material name="white"/>
        </visual>
        <collision>
            <origin xyz="0 0 0.0025"/>
            <geometry>
                <box size="0.2 0.15 0.005"/>
            </geometry>
        </collision>
        <xacro:inertial_box mass="0.015" x="0.2" y="0.15" z="0.005">
            <origin xyz= "0 0 0.0025" rpy="0 0 0"/>
        </xacro:inertial_box>

        <!-- front chassis -->
        <visual>
            <origin xyz="0.115 0 0.0025"/>
            <geometry>
                <box size="0.03 0.2 0.005"/>
            </geometry>
            <material name="white"/>
        </visual>
        <collision>
            <origin xyz="0.115 0 0.0025"/>
            <geometry>
                <box size="0.03 0.2 0.005"/>
            </geometry>
        </collision>
        <xacro:inertial_box mass="0.005" x="0.03" y="0.2" z="0.005">
            <origin xyz= "0.115 0 0.0025" rpy="0 0 0"/>
        </xacro:inertial_box>
        
        <!-- back chassis -->
        <visual>
            <origin xyz="-0.115 0 0.0025"/>
            <geometry>
                <box size="0.03 0.2 0.005"/>
            </geometry>
            <material name="white"/>
        </visual>
        <collision>
            <origin xyz="-0.115 0 0.0025"/>
            <geometry>
                <box size="0.03 0.2 0.005"/>
            </geometry>
        </collision>
        <xacro:inertial_box mass="0.005" x="0.03" y="0.2" z="0.005">
            <origin xyz= "-0.115 0 0.0025" rpy="0 0 0"/>
        </xacro:inertial_box>

        <!-- Front_Right_spacer -->
        <visual>
            <origin xyz="0.115 0.0875 0.0225"/>
            <geometry>
                <cylinder radius = "0.0055" length="0.04"/>
            </geometry>
            <material name="white"/>
        </visual>
        <collision>
            <origin xyz="0.115 0.0875 0.0225"/>
            <geometry>
                <cylinder radius = "0.0055" length="0.04"/>
            </geometry>
        </collision>
        <xacro:inertial_cylinder mass="0.005" length="0.04" radius="0.0055">
            <origin xyz= "0.115 0.0875 0.0225" rpy="0 0 0"/>
        </xacro:inertial_cylinder>

        <!-- Front_Left_spacer -->
        <visual>
            <origin xyz="0.115 -0.0875 0.0225"/>
            <geometry>
                <cylinder radius = "0.0055" length="0.04"/>
            </geometry>
            <material name="white"/>
        </visual>
        <collision>
            <origin xyz="0.115 -0.0875 0.0225"/>
            <geometry>
                <cylinder radius = "0.0055" length="0.04"/>
            </geometry>
        </collision>
        <xacro:inertial_cylinder mass="0.005" length="0.04" radius="0.0055">
            <origin xyz= "0.115 -0.0875 0.0225" rpy="0 0 0"/>
        </xacro:inertial_cylinder>

        <!-- Back_Right_spacer -->
        <visual>
            <origin xyz="-0.115 0.0875 0.0225"/>
            <geometry>
                <cylinder radius = "0.0055" length="0.04"/>
            </geometry>
            <material name="white"/>
        </visual>
        <collision>
            <origin xyz="-0.115 0.0875 0.0225"/>
            <geometry>
                <cylinder radius = "0.0055" length="0.04"/>
            </geometry>
        </collision>
        <xacro:inertial_cylinder mass="0.005" length="0.04" radius="0.0055">
            <origin xyz= "-0.115 0.0875 0.0225" rpy="0 0 0"/>
        </xacro:inertial_cylinder>

        <!-- Back_left_spacer -->
        <visual>
            <origin xyz="-0.115 -0.0875 0.0225"/>
            <geometry>
                <cylinder radius = "0.0055" length="0.04"/>
            </geometry>
            <material name="white"/>
        </visual>
        <collision>
            <origin xyz="-0.115 -0.0875 0.0225"/>
            <geometry>
                <cylinder radius = "0.0055" length="0.04"/>
            </geometry>
        </collision>
        <xacro:inertial_cylinder mass="0.005" length="0.04" radius="0.0055">
            <origin xyz= "-0.115 -0.0875 0.0225" rpy="0 0 0"/>
        </xacro:inertial_cylinder>


        <!--Second stage-->                                     <!--Second stage-->

        <visual>
            <origin xyz="0 0 0.0425"/>
            <geometry>
                <box size="0.2 0.15 0.005"/>
            </geometry>
            <material name="white"/>
        </visual>
        <collision>
            <origin xyz="0 0 0.0425"/>
            <geometry>
                <box size="0.2 0.15 0.005"/>
            </geometry>
        </collision>
        <xacro:inertial_box mass="0.015" x="0.2" y="0.15" z="0.005">
            <origin xyz= "0 0 0.0425" rpy="0 0 0"/>
        </xacro:inertial_box>

        <!-- front chassis -->
        <visual>
            <origin xyz="0.115 0 0.0425"/>
            <geometry>
                <box size="0.03 0.2 0.005"/>
            </geometry>
            <material name="white"/>
        </visual>
        <collision>
            <origin xyz="0.115 0 0.0425"/>
            <geometry>
                <box size="0.03 0.2 0.005"/>
            </geometry>
        </collision>
        <xacro:inertial_box mass="0.005" x="0.03" y="0.2" z="0.005">
            <origin xyz= "0.115 0 0.0425" rpy="0 0 0"/>
        </xacro:inertial_box>
        
        <!-- back chassis -->
        <visual>
            <origin xyz="-0.115 0 0.0425"/>
            <geometry>
                <box size="0.03 0.2 0.005"/>
            </geometry>
            <material name="white"/>
        </visual>
        <collision>
            <origin xyz="-0.115 0 0.0425"/>
            <geometry>
                <box size="0.03 0.2 0.005"/>
            </geometry>
        </collision>
        <xacro:inertial_box mass="0.005" x="0.03" y="0.2" z="0.005">
            <origin xyz= "-0.115 0 0.0425" rpy="0 0 0"/>
        </xacro:inertial_box>

        <!-- Front_Right_spacer -->
        <visual>
            <origin xyz="0.115 0.0875 0.0625"/>
            <geometry>
                <cylinder radius = "0.0055" length="0.04"/>
            </geometry>
            <material name="white"/>
        </visual>
        <collision>
            <origin xyz="0.115 0.0875 0.0625"/>
            <geometry>
                <cylinder radius = "0.0055" length="0.04"/>
            </geometry>
        </collision>
        <xacro:inertial_cylinder mass="0.005" length="0.04" radius="0.0055">
            <origin xyz= "0.115 0.0875 0.0625" rpy="0 0 0"/>
        </xacro:inertial_cylinder>

        <!-- Front_Left_spacer -->
        <visual>
            <origin xyz="0.115 -0.0875 0.0625"/>
            <geometry>
                <cylinder radius = "0.0055" length="0.04"/>
            </geometry>
            <material name="white"/>
        </visual>
        <collision>
            <origin xyz="0.115 -0.0875 0.0625"/>
            <geometry>
                <cylinder radius = "0.0055" length="0.04"/>
            </geometry>
        </collision>
        <xacro:inertial_cylinder mass="0.005" length="0.04" radius="0.0055">
            <origin xyz= "0.115 -0.0875 0.0625" rpy="0 0 0"/>
        </xacro:inertial_cylinder>

        <!-- Back_Right_spacer -->
        <visual>
            <origin xyz="-0.115 0.0875 0.0625"/>
            <geometry>
                <cylinder radius = "0.0055" length="0.04"/>
            </geometry>
            <material name="white"/>
        </visual>
        <collision>
            <origin xyz="-0.115 0.0875 0.0625"/>
            <geometry>
                <cylinder radius = "0.0055" length="0.04"/>
            </geometry>
        </collision>
        <xacro:inertial_cylinder mass="0.005" length="0.04" radius="0.0055">
            <origin xyz= "-0.115 0.0875 0.0625" rpy="0 0 0"/>
        </xacro:inertial_cylinder>

        <!-- Back_left_spacer -->
        <visual>
            <origin xyz="-0.115 -0.0875 0.0625"/>
            <geometry>
                <cylinder radius = "0.0055" length="0.04"/>
            </geometry>
            <material name="white"/>
        </visual>
        <collision>
            <origin xyz="-0.115 -0.0875 0.0625"/>
            <geometry>
                <cylinder radius = "0.0055" length="0.04"/>
            </geometry>
        </collision>
        <xacro:inertial_cylinder mass="0.005" length="0.04" radius="0.0055">
            <origin xyz= "-0.115 -0.0875 0.0625" rpy="0 0 0"/>
        </xacro:inertial_cylinder>


        <!--Third stage-->                                     <!--Third stage-->

        <visual>
            <origin xyz="0 0 0.0825"/>
            <geometry>
                <box size="0.2 0.15 0.005"/>
            </geometry>
            <material name="white"/>
        </visual>
        <collision>
            <origin xyz="0 0 0.0825"/>
            <geometry>
                <box size="0.2 0.15 0.005"/>
            </geometry>
        </collision>
        <xacro:inertial_box mass="0.015" x="0.2" y="0.15" z="0.005">
            <origin xyz= "0 0 0.0825" rpy="0 0 0"/>
        </xacro:inertial_box>

        <!-- front chassis -->
        <visual>
            <origin xyz="0.115 0 0.0825"/>
            <geometry>
                <box size="0.03 0.2 0.005"/>
            </geometry>
            <material name="white"/>
        </visual>
        <collision>
            <origin xyz="0.115 0 0.0825"/>
            <geometry>
                <box size="0.03 0.2 0.005"/>
            </geometry>
        </collision>
        <xacro:inertial_box mass="0.005" x="0.03" y="0.2" z="0.005">
            <origin xyz= "0.115 0 0.0825" rpy="0 0 0"/>
        </xacro:inertial_box>
        
        <!-- back chassis -->
        <visual>
            <origin xyz="-0.115 0 0.0825"/>
            <geometry>
                <box size="0.03 0.2 0.005"/>
            </geometry>
            <material name="white"/>
        </visual>
        <collision>
            <origin xyz="-0.115 0 0.0825"/>
            <geometry>
                <box size="0.03 0.2 0.005"/>
            </geometry>
        </collision>
        <xacro:inertial_box mass="0.005" x="0.03" y="0.2" z="0.005">
            <origin xyz= "-0.115 0 0.0825" rpy="0 0 0"/>
        </xacro:inertial_box>
    </link> 

    <!-- Wheels -->       <!-- Wheels -->

     <!-- Left Wheel Link-->

    <joint name="left_wheel_joint" type="continuous">
        <parent link= "base_link"/>
        <child link="left_wheel"/>
        <origin xyz="0 0.106 0" rpy="-${pi/2} 0 0"/>
        <axis xyz="0 0 1"/>
        <limit effort="100" velocity="10.0"/>
        <dynamics damping="0.1" friction="0.1"/>
    </joint>

    <link name="left_wheel">
        <visual>
            <geometry>
                <cylinder radius="0.03" length="0.026"/>
            </geometry>
            <material name="blue"/>
        </visual>
        <collision>
            <geometry>
                <cylinder radius="0.03" length="0.026"/>
            </geometry>
        </collision>
        <xacro:inertial_cylinder mass="0.02" length="0.026" radius="0.03">
            <origin xyz= "0 0 0" rpy="0 0 0"/>
        </xacro:inertial_cylinder>
    </link>

    <!-- Right Wheel Link-->

    <joint name="right_wheel_joint" type="continuous">
        <parent link= "base_link"/>
        <child link="right_wheel"/>
        <origin xyz="0. -0.106 0" rpy="${pi/2} 0 0"/>
        <axis xyz="0 0 -1"/>
        <limit effort="100" velocity="10.0"/>
        <dynamics damping="0.1" friction="0.1"/>
    </joint>

    <link name="right_wheel">
        <visual>
            <geometry>
                <cylinder radius="0.03" length="0.026"/>
            </geometry>
            <material name="blue"/>
        </visual>
        <collision>
            <geometry>
                <cylinder radius="0.03" length="0.026"/>
            </geometry>
        </collision>
        <xacro:inertial_cylinder mass="0.02" length="0.026" radius="0.03">
            <origin xyz= "0 0 0" rpy="0 0 0"/>
        </xacro:inertial_cylinder>
    </link>

    <!--Caster Wheel Link -->
    <joint name="caster_wheel_joint" type="fixed">
        <parent link="midle_chassis"/>
        <child link="caster_wheel"/>
        <origin xyz="-0.1 0 0"/>
    </joint>

    <link name="caster_wheel">
        <visual>
            <geometry>
                <sphere radius="0.03"/>
            </geometry>
            <material name="black"/>
        </visual>
        <collision>
            <geometry>
                <sphere radius="0.03"/>
            </geometry>
        </collision>
        <xacro:inertial_sphere mass="0.02" radius="0.03">
            <origin xyz="0 0 0" rpy="0 0 0"/>
        </xacro:inertial_sphere>
    </link>

    <link name="robot_front"/>

    <joint name="chassis_joint_1" type="fixed">
        <parent link= "midle_chassis"/>
        <child link="robot_front"/>
        <origin xyz="0.13 0 0"/>
    </joint>


</robot>